Workbook

Sheet Dashboard
C1: پروژه احداث خط لوله ۱۶ اینچ انتقال فرآورده رفسنجان-یزد و توسعه مراکز انتقال نفت رفسنجان و یزد به روش EPC
C2: داشبورد مدیریتی متریال کل پروژه بر اساس پیمان
A4: جدول خلاصه برآورد تفکیکی بر اساس سرفصل‌های تخصصی پروژه (EPC Summary Table by Discipline)
A6: ردیف | B6: سرفصل پروژه (Project Discipline) | C6: مبلغ ریالی (Rial Part) | D6: مبلغ ارزی (Euro Part) | E6: شیت مرجع تفصیلی (Detailed Sheet Link)
A7: 1 | B7: لوله‌کشی و شیرآلات (Piping & Valves) | C7: =0 -> 0 | D7: ='Piping & Valves'!K29+'Piping & Valves'!K71 -> 1542923.9 | E7: برو به شیت Piping & Valves →
A8: 2 | B8: تجهیزات مکانیکال (Mechanical Equipment) | C8: =Mechanical!J17+Mechanical!J42+Mechanical!J62 -> 126780000000 | D8: =Mechanical!K17+Mechanical!K42+Mechanical!K62 -> 2337532.6 | E8: برو به شیت Mechanical →
A9: 3 | B9: تجهیزات برقی (Electrical Equipment) | C9: =Electrical!J23+Electrical!J46+Electrical!J56 -> 812237187000 | D9: =Electrical!K23+Electrical!K46+Electrical!K56 -> 1901290 | E9: برو به شیت Electrical →
A10: 4 | B10: ابزار دقیق و مخابرات (Instrumentation & Telecom) | C10: =Instrumentation!J47+Instrumentation!J107+Instrumentation!J117 -> 26740000000 | D10: =Instrumentation!K47+Instrumentation!K107+Instrumentation!K117 -> 4776150 | E10: برو به شیت Instrumentation →
A11: 5 | B11: حفاظت کاتدیک (Cathodic Protection) | C11: ='Cathodic Protection'!J14+'Cathodic Protection'!J27+'Cathodic Protection'!J40 -> 29742500000 | D11: ='Cathodic Protection'!K14+'Cathodic Protection'!K27+'Cathodic Protection'!K40 -> 0 | E11: برو به شیت Cathodic Protection →
A12: 6 | B12: ایمنی و آتش‌نشانی (Safety & Fire Fighting) | C12: =0 -> 0 | D12: ='Safety & Fire Fighting'!J15+'Safety & Fire Fighting'!J31 -> 143650 | E12: برو به شیت Safety & Fire Fighting →
A13: 7 | B13: لوازم یدکی دو ساله بهره‌برداری (Spare Parts) | C13: ='Spare Parts'!I11 -> 313000 | D13: ='Spare Parts'!J11 -> 313000 | E13: برو به شیت Spare Parts →
A14: 8 | B14: آموزش کارکنان کارفرما و بهره بردار | C14: 4500000000 | D14: 0
A15: جمع کل ارزش پروژه (Grand Total) | C15: =SUM(C7:C14) -> 1000000000000 | D15: =SUM(D7:D14) -> 11014546
A16: جدول شماره ۲: تفکیک برآورد کل پروژه بر اساس (سند اصلی)
A17: ردیف | B17: موقعیت و بخش پروژه (Location / Section) | C17: مبلغ ریالی سند اصلی (Rials) | D17: مبلغ ارزی سند اصلی (Euros) | E17: توضیحات تراز و مغایرت محاسباتی
A18: 1 | B18: هزینه تهیه و تأمین کالا در تلمبه‌خانه رفسنجان (جدول ۱-۲) | C18: 492010187000 | D18: 4355480 | E18: تطابق کامل با ریز متره دیسیپلین‌ها (با احتساب ۱,۳۱۰ یورو اختلاف ابزار دقیق) آیتم 3 درپیمان تعداد 2 عدد می بایست محاسبه می شده است اما یک عدد محاسبه شده
A19: 2 | B19: هزینه تهیه و تأمین کالا در تلمبه‌خانه یزد (جدول ۲-۲) | C19: 277249500000 | D19: 5782446 | E19: تطابق کامل با ریز متره دیسیپلین‌ها
A20: 3 | B20: هزینه تهیه و تأمین کالا خط لوله ۱۶ اینچ رفسنجان-یزد (جدول ۳-۲) | C20: 226240000000 | D20: 563620 | E20: تطابق کامل با ریز متره دیسیپلین‌ها
A21: 4 | B21: تأمین لوازم یدکی و مواد مصرفی پیش راه‌اندازی و دو ساله (جدول ۴-۲) | C21: 313000 | D21: 313000 | E21: دو عدد هم در ریالی قرار گرفته هم در یورویی
B22: آموزش کارکنان کارفرما و بهره بردار | C22: 4500000000 | D22: 0
A23: جمع محاسباتی سند اصلی (Calculated Sum with Typos) | C23: =SUM(C18:C22) -> 1000000000000 | D23: =SUM(D18:D21) -> 11014546

Sheet توضیحات1
B4: خلاصه متریال ( به فارسی - انگلیسی)

Sheet Master Merged View (خلاصه کل)
A1: جدول جامع و فوق‌فشرده برآورد متریال کل پروژه به تفکیک سرفصل‌های تخصصی
A2: پروژه احداث خط لوله ۱۶ اینچ انتقال فرآورده رفسنجان-یزد و توسعه مراکز انتقال نفت رفسنجان و یزد به روش EPC
A3: ردیف | B3: سرفصل پروژه (Discipline) | C3: اقلام تفصیلی، ابعاد و مشخصات فنی ادغام‌یافته | D3: تعداد / متراژ کل پروژه | E3: شرح بسیار خلاصه سرفصل | F3: شیت مرجع
A4: 1 | B4: لوله‌کشی و شیرآلات (Piping & Valves) | C4: • Pipe (لوله): سایزهای "8, "12, "14, "16, "18, "28 (متراژ کل: ۵,۲۶۰ متر) • Gate Valve (شیر دروازه‌ای): سایزهای "6, "12, "14, "16 (تعداد کل: ۲۳ عدد) • Check Valve (شیر خودکار): سایزهای "6, "12, "14, "18, "28 (تعداد کل: ۴۱ عدد) • Ball Valve (شیر توپی): سایزهای "6, "8, "12, "14, "18, "28 (تعداد کل: ۳۰ عدد) • Chock Valve (شیر چوک): سایز "8 (تعداد کل: ۴ عدد) • Globe Valve (شیر کروی): سایز "14 (تعداد کل: ۱ عدد) • Expansion Joint (لرزه‌گیر آکاردئونی): سایزهای "14, "18, "28 (تعداد کل: ۶ عدد) • (تعداد کل: ۲ ست) Bulk Equipment (اتصالات فله): سایز Bulk | D4: ۵,۲۶۰ متر لوله ۱۰۵ عدد انواع شیرآلات ۲ ست تجهیزات فله | E4: لوله‌ها و اتصالات فولادی فشار قوی خطوط فرآورده و شیرآلات صنعتی تا کلاس کاری ۱۵۰۰. | F4: Piping & Valves
A5: 2 | B5: تجهیزات مکانیکال (Mechanical Equipment) | C5: • MAIN PUMP (پمپ‌های اصلی): برقی (MP-451/452/453) و دیزلی (MP-554) (تعداد کل: ۷ عدد) • BOOSTER PUMP (بوستر پمپ‌ها و پمپ‌های فرعی): بوستر پمپ‌های BP-451 و BP-551، پمپ‌های تزریق مجدد P-551 و پمپ‌های تخلیه (تعداد کل: ۱۲ عدد) • Pig Trap (تله‌های ارسال/دریافت پیگ): سایز "16x"20 کلاس ۹۰۰# گرید X60 (تعداد کل: ۲ ست کامل) • Corrosion Inhibitor Package (پکیج تزریق ضدخوردگی): مدل‌های PK-451 و PK-551 (تعداد کل: ۲ ست) • Cranes (جرثقیل‌ها): جرثقیل سقفی ۱۵ تن، کارگاهی ۵ تن و بازویی ۱ تن با متعلقات کامل (تعداد کل: ۹ عدد) • Tanks (مخازن فرآیندی/سوخت): ظرفیت‌های ۲۰ و ۳۰ مترمکعب دفنی تحت فشار (تعداد کل: ۳ دستگاه) • Main Strainer (صافی‌های اصلی): کلاس‌های کاری ۶۰۰# و ۹۰۰# تلمبه‌خانه‌ها (تعداد کل: ۸ عدد) • Hot Bend (خم‌های گرم خط لوله): سایز "16 زاویه ۴۵ درجه با شعاع 7D گرید X60 (تعداد کل: ۱۲ عدد) • Pipeline Valves (شیرآلات خط لوله): شیرآلات بین‌راهی "16 کلاس ۹۰۰# (شامل LBV با پنل خورشیدی، Block، Check) (تعداد کل: ۹ عدد) • Anchor & Insulating Flange (اتصالات مهار و عایقی): سایز "16 کلاس ۹۰۰# گرید F60 (تعداد کل: ۴ عدد) • Power Pack Unit & Casing (پاورپک و غلاف کیسینگ): پاورپک بنزینی هیدرولیک و لوله کیسینگ "20 عبوری راه آهن (تعداد کل: ۲ ست پاورپک، ۶۰۰ متر کیسینگ) • Field Joint Coating (پوشش سرجوش): سیستم دو لایه FBE سرجوش‌ها و پوشش‌های مایع اپوکسی (تعداد کل: ۲۰,۰۰۰ عدد پوشش) | D5: ۵۸ عدد انواع پمپ و تجهیزات اصلی ۲۰,۰۰۰ عدد پوشش سرجوش FBE ۲ ست تجهیزات مکانیکی فله | E5: پمپ‌های پرقدرت انتقال فرآورده و بوستری، تله‌های پیگ‌رانی، خم‌های خط لوله و شیرآلات کنترلی بین‌راهی. | F5: Mechanical
A7: 3 | B7: تجهیزات برقی (Electrical Equipment) | C7: • Medium Voltage Cable (کابل‌های فشار متوسط): سایزهای 1x240 و 3x185 رده ۱۲/۲۰kV سربی زره‌دار سربی (Lead Cover / SWA) (متراژ کل: ۱۲,۳۶۰ متر) • Low Voltage Cable (کابل‌های فشار ضعیف): هادی‌های مسی زره‌دار 3x240+120 و 3x120+70 و 3x95 و 1x120 و 1x95 (متراژ کل: ۳,۲۷۰ متر) • MV/LV Switchgears (تابلوهای برق): رده‌های ۶kV و ۲۰kV مجهز به بریکر خلاء (VCB) و تابلوهای LV رده ۰.۴kV (ظرفیت ۵۰kA) (تعداد کل: ۸ ست) • Power Transformers (ترانس‌های قدرت): ظرفیت پرقدرت ۱۲۵۰۰kVA رده ۲۰/۶.۳kV و توزیع ۳۰۰kVA و ۵۰kVA کنسرواتوری (تعداد کل: ۹ دستگاه) • UPS & Battery Chargers (یو‌پی‌اس و شارژر): سیستم‌های دوگانه ۲۳۰VAC ظرفیت ۲۰kVA و ۱۱۰VDC توان ۵kW با بانک‌های باتری ۱۰۰% (تعداد کل: ۴ ست) • AAAC Conductor Wire (سیم هادی توزیع هوایی): خط توزیع ۲۰ کیلوولت آلومینیومی روکش‌دار ایستگاه‌ها (متراژ کل: ۲۰ کیلومتر) • Diesel Emergency Generator (دیزل ژنراتور اضطراری): ظرفیت ۳۰۰kVA خروجی ۴۰۰V برای تلمبه‌خانه یزد مجهز به ATS (تعداد کل: ۱ دستگاه) • Bulk Electrical (ملزومات فله برقی): سیستم‌های روشنایی، اتصالات ارت، کابل‌کشی عمومی و ملزومات برق ایستگاه‌های کاتدیک (تعداد کل: ۳ ست) | D7: ۱۵,۶۳۰ متر کابل‌کشی مسی زره‌دار ۲۰ کیلومتر خط انتقال هوایی برق ۲۲ ست انواع تابلو، ترانسفورمر و سیستم برق اضطراری | E7: کابل‌های مسی زره‌دار سربی فشار متوسط و ضعیف، پست‌های برق با تابلوهای خلاء، ترانسفورماتورهای فوق پرقدرت و برق اضطراری. | F7: Electrical
A8: 4 | B8: ابزار دقیق و مخابرات (Instrumentation & Telecom) | C8: • F&G / Control Systems (اعلان حریق و کنترل): سیستم اعلان حریق تحت پردازنده و سیستم کنترل کانسول‌های ESD و PCS تحت شبکه PLC با ریداندانت دوگانه (تعداد کل: ۴ ست) • Motor Actuated Valves (ولوهای موتوردار): سایزهای "4 تا "28 کلاس‌های ۱۵۰ الی ۱۵۰۰ مجهز به اکچویتور برقی ۴۰۰VAC (MOV) (تعداد کل: ۵۴ عدد) • Ultrasonic Flow Meters (فلومترهای اولتراسونیک): سایز "16 رده‌های ۶۰۰# و ۹۰۰# مجهز به مسیرهای اندازه‌گیری چندکاناله (تعداد کل: ۸ ست) • Transmitters & Instruments (حسگرها و فرستنده‌ها): سنجش فشار، دما، سطح و دانسیته مجهز به مانیفولدهای ۶۰۰۰# و آلیاژ ضدخوردگی Monel (تعداد کل: ۱۶۷ عدد) • Relief & Control Valves (شیرهای ایمنی و کنترل جریان): شیر کنترل دبی "12 کلاس ۱۵۰۰ رینگ‌جوینت و شیرهای اطمینان حرارتی و فشاری (تعداد کل: ۵۷ عدد) • Telecom Systems (مخابرات و تلفن): سیستم تلفن تحت شبکه IP، سیستم پیجینگ صنعتی مجراها و دوربین‌های مداربسته امنیتی CCTV (تعداد کل: ۱۲ ست) • Fiber Optic Cable (خط فیبر نوری خط لوله): کابل سینگل‌مود زره‌دار فولادی مسلح ۱۶ هسته‌ای مسیر انتقال به همراه کلوزرباکس‌ها (متراژ کل: ۴,۰۰۰ متر) • Tank Gauging System (TGS): ترانسمیترهای راداری سطح، فرستنده چند نقطه‌ای دما و نمایشگر محلی (تعداد کل: ۳ ست) • Bulk I&C (ملزومات فله ابزار دقیق): ملزومات کابل‌کشی ابزار دقیق، تیوبینگ‌های اتصال و متعلقات کارهای عمومی (تعداد کل: ۳ ست) | D8: ۴,۰۰۰ متر کابل فیبر نوری زره‌دار ۲۴۰ عدد انواع شیر موتوردار و فلومتر اولتراسونیک ۱۹۸ عدد انواع ترانسمیتر دقیق و سیستم‌های مخابراتی | E8: سامانه‌های مانیتورینگ دقیق فرآیند، شیرآلات کنترل موتوردار پرسرعت، حسگرهای Eexd، شبکه فیبر نوری مجهز به مانیتورینگ دوربین و پیجینگ. | F8: Instrumentation
A9: 5 | B9: حفاظت کاتدیک (Cathodic Protection) | C9: • Transformer Rectifiers (رکتیفایرهای کاتدیک): رده‌های هوشمند خودکار ۵۰V/۲۵A و ۵۰V/۵۰A روغنی فضای باز با پایه بتنی (تعداد کل: ۵ دستگاه) • Anodes (آندهای حفاظت کاتدی): آندهای سیمی MMO، آند چدن پرسیلیس HSCI رده "3x"60، آند منیزیم ۳۲ پوندی و آند روی موقت ۱۰ پوندی (تعداد کل: ۸۲۰ عدد) • Coke Breeze Backfill (پشت‌بند کک نفتی): کک نفتی کربن بالای ۹۰% نوع ۲ دانه ریز مطابق استاندارد IPS-M-TP-750 (وزن کل: ۱۳,۵۰۰ کیلوگرم) • Zinc Earthing Cell (سلول‌های ارت زمین): مشخصات ابعادی 36x36x1520mm به همراه ۱۰ متر کابل مسی XLPE (تعداد کل: ۲ عدد) • Bulk CP (ملزومات فله کاتدیک): کابل‌های اتصالی مسی، تست باکس‌ها، اتصالات باندینگ خط لوله و جعبه‌های توزیع جریان (تعداد کل: ۳ ست) | D9: ۵ دستگاه ترانسفورمر رکتیفایر هوشمند ۸۲۲ عدد انواع آند MMO، چدنی، منیزیم و روی و سلول ارت ۱۳.۵ تن مواد پشت‌بند کک نفتی کربن بالا | E9: تجهیزات حفاظت اکتیو و غیرفعال خط در برابر خوردگی خاک شامل ترانس‌های رکتیفایر هوشمند، بستر آندهای عمیق چدن و منیزیم. | F9: Cathodic Protection
A10: 6 | B10: ایمنی و آتشنشانی (Safety & Fire Fighting) | C10: • Water Hydrants (هیدرانت‌ها و مانیتورها): پکیج هیدرانت‌های مجهز به ورودی شیر کنترل، محافظ بدنه و مانیتورهای آتش‌نشانی ثابت سالن‌ها (تعداد کل: ۱۲ ست) • Fire Extinguishers (کپسول‌های حریق): کپسول‌های پودر خشک دستی ۱۲ کیلوگرمی و چرخ‌دار ۷۵ کیلوگرمی به همراه کپسول‌های گازی CO2 رده ۶kg و ۳۰kg (تعداد کل: ۳۸ عدد) • Total Flooding Systems (سیستم اطفای گازی): پکیج اطفای اتوماتیک سیلابی گاز بی‌اثر (Inert Gas) مجهز به لوله‌کشی و سیلندرهای تحت فشار (تعداد کل: ۲ ست) • Bulk Safety (ملزومات فله ایمنی): جعبه‌های شلنگ آب آتش‌نشانی، تجهیزات ایمنی فردی، سیستم‌های دستی اضطراری سالن پمپ‌ها (تعداد کل: ۲ ست) | D10: ۱۲ ست هیدرانت و مانیتور آتش صنعتی ۳۸ کپسول اطفاء پرتابل پودری و CO2 ۴ ست پکیج سیلابی گازی و متعلقات فله ایمنی | E10: رینگ هیدرانت‌ها و مانیتورهای توزیع آب آتش‌نشانی ایستگاه‌ها، تجهیزات اطفای سیلابی گازی فضاهای حساس الکترونیکی و کپسول‌های پرتابل. | F10: Safety & Fire Fighting
A11: 7 | B11: لوازم یدکی دو ساله بهرهبرداری (Spare Parts) | C11: • Rafsanjan Spares (یدکی‌های ایستگاه رفسنجان): قطعات یدکی پمپ‌ها، تجهیزات ابزار دقیق و برقی مصرفی پیش‌راه‌اندازی ایستگاه (تعداد کل: ۱ پکیج) • Yazd Spares (یدکی‌های ایستگاه یزد): لوازم یدکی قطعات گردان مکانیکی و ابزار دقیق دو ساله بهره‌برداری مداوم (تعداد کل: ۱ پکیج) • Pipeline Spares (یدکی‌های خط لوله): لوازم یدکی شیرآلات پرسرعت بین‌راهی خط لوله، اکچویتورهای هیدرولیک و اتصالات مسیر انتقال (تعداد کل: ۱ پکیج) | D11: ۳ پکیج جامع مقطوع (شامل قطعات یدکی رفسنجان، یزد و خط لوله ۱۶ اینچ) | E11: قطعات مصرفی دوره پیش‌راه‌اندازی و قطعات یدکی مکانیکی، برقی و ابزار دقیق با کارکرد دو ساله کل تاسیسات پروژه. | F11: Spare Parts

Sheet Master Merged View (English)
A1: Comprehensive & Consolidated Project Materials Estimate by Special Disciplines
A2: EPC Project for Constructing 16" Rafsanjan-Yazd Product Pipeline & Developing Rafsanjan and Yazd Pump Stations
A3: Item | B3: Project Discipline | C3: Detailed Consolidated Items & Technical Specs (English ONLY) | D3: Project Total Quantity | E3: Brief Scope Description | F3: Reference Sheet
A4: 1 | B4: Piping & Valves | C4: • Pipe: Sizes 8", 12", 14", 16", 18", 28" (Total Qty: 5,260 M) • Gate Valve: Sizes 6", 12", 14", 16" (Total Qty: 23 NO) • Check Valve: Sizes 6", 12", 14", 18", 28" (Total Qty: 41 NO) • Ball Valve: Sizes 6", 8", 12", 14", 18", 28" (Total Qty: 30 NO) • Chock Valve: Size 8" (Total Qty: 4 NO) • Globe Valve: Size 14" (Total Qty: 1 NO) • Expansion Joint: Sizes 14", 18", 28" (Total Qty: 6 NO) • Bulk Piping: General accessories (Total Qty: 2 Bulk) | D4: 5,260 M Pipes 105 NO Valves 2 Bulk Sets | E4: High-pressure steel piping, valves, and joints up to class 1500. | F4: Piping & Valves
A5: 2 | B5: Mechanical Equipment | C5: • Main Transfer Pumps: Electrical MP-451/452/453 & MP-551/552/553, Diesel MP-554 (Total Qty: 7 NO) • Booster & Auxiliary Pumps: Main Booster Pumps BP-451 A/B/C & BP-551 A/B/C, Re-injection P-551 A/B, Close Drain P-552, Dirty Drain P-553, Fuel P-560 (Total Qty: 12 NO) • Process Tanks: Buried underground horizontal pressure tanks 20 m3 and 30 m3 (Total Qty: 3 NO) • Pig Traps: 16"x20" Pig Launcher Trap S-432, Receiver Trap S-551, Class 900# API 5L X60 (Total Qty: 2 SET) • Cranes: Overhead manual cranes 15 Ton, 5 Ton, Jib cranes 1 Ton (Total Qty: 9 NO) • Pipeline Equipment: Main strainers 600# & 900#, hot bends 16", insulated flanges, anchor flanges, field joint coatings, rail casing (Total Qty: 8 Strainers, 12 Hot Bends, 4 Insulating/Anchor, 20,000 FBE Coatings, 600m Casing) | D5: 58 NO/SET Core Equipments 20,000 FBE Joint Coatings 2 Bulk Mechanical Sets | E5: High-capacity transfer pumps, pig traps, cranes, vessels, and bends. | F5: Mechanical
A6: 3 | B6: Electrical Equipment | C6: • Medium Voltage Cables: 1x240, 3x185, 12/20kV & 6/10kV copper SWA lead covered (Total Qty: 12,360 M) • Low Voltage Cables: 3x240+120, 3x120+70, 3x95, 1x120, 1x95 copper SWA lead covered (Total Qty: 3,270 M) • MV/LV Switchgears: 20kV MV switchgears (VCB 25kA/1s), 6kV withdrawable vacuum type (1600A), 0.4kV LV switchgears, power factor panels (Total Qty: 8 SET) • Power Transformers: 12500kVA 20/6.3kV ONAN transformers, distribution 300kVA & 50kVA transformers (Total Qty: 9 NO) • UPS & Battery Chargers: 230VAC UPS dual system 20kVA (100% battery bank), 110VDC charger dual system 5kW (Total Qty: 4 SET) • Power Transmission Line: 20kV overhead line with AAAC aluminum conductor wire (Total Qty: 20 KM) • Diesel Emergency Generator: 300kVA 400V generator with ATS (Total Qty: 1 NO) • Bulk Electrical: Lighting, grounding, cabling, trays and cathodic protection power supplies | D6: 15,630 M Copper Armored Cables 20 KM Overhead Distribution Line 22 SET Switchgears, Transformers, Emergency UPS | E6: Power substations, armored copper cables, switchgears, and power grids. | F6: Electrical
A7: 4 | B7: Instrumentation & Telecom | C7: • F&G / Control Systems: Microprocessor-based Fire & Gas control panel, PLC-based PCS & ESD dual redundant control systems (Total Qty: 4 SET) • Motor Actuated Valves (MOV): Ball valves 4" to 28", classes 150# to 1500# with 400VAC actuators (Total Qty: 54 NO) • Ultrasonic Flow Meters: 16" inline meters class 600# and 900# RF/RTJ (Total Qty: 8 NO) • Transmitters & Indicators: Pressure, temperature, level, DP transmitters with 316SS wetted parts and 6000# manifolds (Total Qty: 167 NO) • Relief & Control Valves: Globe control valves 12" class 1500, pressure/temperature relief valves, restriction orifices (Total Qty: 57 NO) • Telecom Systems: IP-based telephone systems, industrial paging cabinet and speakers, CCTV security system, LAN server and switches (Total Qty: 12 SET) • Fiber Optic Cable: 16-Core single-mode armored optic cable with closure boxes/patch panels (Total Qty: 4,000 M) • Tank Gauging System (TGS): Radar level transmitters, multipoint temp transmitters, local indicators (Total Qty: 3 SET) • Bulk I&C: Cables, tubing, fittings and installation accessories | D7: 4,000 M Armored Fiber Optic 240 NO Motorized & Control Valves 198 SET Instruments & Transmitters | E7: Process monitoring systems, motorized valves, meters, sensors, and telecom. | F7: Instrumentation
A8: 5 | B8: Cathodic Protection | C8: • Transformer Rectifiers: Outdoor smart automatic oil-immersed units 50V/25A and 50V/50A on concrete pads (Total Qty: 5 NO) • CP Anodes: MMO wire anodes, HSCI rod anodes (3"x60" 50kg), magnesium high-potential anodes (32 lb), zinc temporary anodes (10 lb) (Total Qty: 820 NO) • Materials: Petroleum coke breeze backfill type 2 (>90% Carbon) for deep well bed (Total Qty: 13,500 Kg) • Earthing Cells: Zinc earthing cells (36x36x1520mm) prepackaged with special backfill and cables (Total Qty: 2 NO) • Bulk CP: Testing/bonding junction boxes, copper cabling and connection kits | D8: 5 NO Smart Transformer Rectifiers 822 NO MMO, HSCI, Zinc, Magnesium Anodes 13.5 Tons Coke Breeze Materials | E8: Corrosion prevention systems, rectifiers, anodes, backfills, and grounding. | F8: Cathodic Protection
A9: 6 | B9: Safety & Fire Fighting | C9: • Water Hydrants & Monitors: Hydrants with valve inlets, fixed monitors, bumpers and year-round safety accessories (Total Qty: 12 SET) • Fire Extinguishers: Portable CO2 (6kg, 30kg) and dry powder (12kg, wheeled 75kg) extinguishers (Total Qty: 38 NO) • Gaseous Total Flooding Systems: Inert Gas (Non-CO2 gas) automatic total flooding packages for Control Room and Diesel Generator Building (Total Qty: 2 SET) • Bulk Safety: Hose boxes, fire equipment cabinets, personal protective gear and station signage | D9: 12 SET Hydrants & Fire Monitors 38 NO Dry Powder & CO2 Extinguishers 4 SET Gaseous Flooding & Accessories | E9: Active and passive fire extinguishing systems, hydrants, and safety gear. | F9: Safety & Fire Fighting
A10: 7 | B10: Spare Parts | C10: • Rafsanjan Station Spares: Pump components, instrumentation consumables and startup spare parts (Total Qty: 1 Package) • Yazd Station Spares: Two-year operating mechanical, electrical and structural spare parts (Total Qty: 1 Package) • Pipeline Spares: Spare parts for line block valves, hydraulic actuator kits and connection spares (Total Qty: 1 Package) | D10: 3 Packages (Pre-commissioning consumables & two-year operating spares) | E10: Two-year operating mechanical and electrical spare parts packages. | F10: Spare Parts

Sheet توضیحات2 
B4: فصل بندی متریال براساس جدول ذیل

Sheet توضیحات3 
B4: متریال ( Piping & Valves)

Sheet Piping & Valves
D1: پروژه احداث خط لوله ۱۶ اینچ انتقال فرآورده رفسنجان-یزد و توسعه مراکز انتقال نفت رفسنجان و یزد به روش EPC
E2: بخش لوله‌کشی و شیرآلات (Piping & Valves)
B3: ◀ بازگشت به داشبورد
B5: جدول شماره ۱-۱-۲: قیمت پیشنهادی برای خرید تجهیزات لوله‌کشی تلمبه‌خانه رفسنجان
A6: unit | B6: ردیف (Item) | C6: عنوان | D6: شرح تجهیزات (Description) خلاصه | E6: سایز (Size) | F6: واحد (Unit) | G6: مقدار (Qty) | H6: بهای واحد ریالی (Unit Rial) | I6: بهای واحد ارزی (Unit Euro) | J6: بهای کل ریالی (Total Rial) | K6: بهای کل ارزی (Total Euro) | L6: توضیحات پیمان
A7: تجهیزات لوله‌کشی تلمبه‌خانه رفسنجان | B7: 1 | C7: Pipe | D7: SCH 30 - 8" Pipe | E7: 8" | F7: M | G7: 96 | H7: 0 | I7: 45 | J7: =G7*H7 -> 0 | K7: =G7*I7 -> 4320 | L7: PIPE HFW WELDED, API 5L GRADE B, DOUBLE RANDOM LENGTHS OF 12 M. BEVELED END,BEVEL ENDS PER ANSI B 16.25., DIMENSIONS AND TOLERANCES TO ASME B36.10, TESTING, MARKING TO API 5L AND SPECIFICTION NO. 870063-B-00-XXX-00-101-PI-0034. AND attachment 10 of contract.
A8: تجهیزات لوله‌کشی تلمبه‌خانه رفسنجان | B8: 2 | C8: Pipe | D8: SCH 80 - 8" Pipe | E8: 8" | F8: M | G8: 72 | H8: 0 | I8: 45 | J8: =G8*H8 -> 0 | K8: =G8*I8 -> 3240
A9: تجهیزات لوله‌کشی تلمبه‌خانه رفسنجان | B9: 3 | C9: Pipe | D9: SCH 100 - 8" Pipe | E9: 8" | F9: M | G9: 72 | H9: 0 | I9: 45 | J9: =G9*H9 -> 0 | K9: =G9*I9 -> 3240
A10: تجهیزات لوله‌کشی تلمبه‌خانه رفسنجان | B10: 4 | C10: Pipe | D10: SCH 30 - 12" Pipe | E10: 12" | F10: M | G10: 150 | H10: 0 | I10: 64 | J10: =G10*H10 -> 0 | K10: =G10*I10 -> 9600
A11: تجهیزات لوله‌کشی تلمبه‌خانه رفسنجان | B11: 5 | C11: Pipe | D11: SCH STD - 16" Pipe | E11: 16" | F11: M | G11: 500 | H11: 0 | I11: 124 | J11: =G11*H11 -> 0 | K11: =G11*I11 -> 62000
A12: تجهیزات لوله‌کشی تلمبه‌خانه رفسنجان | B12: 6 | C12: Pipe | D12: PIPE HFW WELDED, API 5L GRADE X52, DOUBLE RANDOM LENGTHS OF 12 M. BEVELED END,BEVEL ENDS PER ANSI B 16.25., DIMENSIONS AND TOLERANCES TO ASME B36.10, TESTING, MARKING TO API 5L SCH 60 - 14" Pipe | E12: 14" | F12: M | G12: 300 | H12: 0 | I12: 165 | J12: =G12*H12 -> 0 | K12: =G12*I12 -> 49500 | L12: PIPE HFW WELDED, API 5L GRADE X52, DOUBLE RANDOM LENGTHS OF 12 M. BEVELED END,BEVEL ENDS PER ANSI B 16.25., DIMENSIONS AND TOLERANCES TO ASME B36.10, TESTING, MARKING TO API 5L AND SPECIFICTION NO. 870063-B-00-XXX-00-101-PI-0034.AND attachment 10 of contract.
A13: تجهیزات لوله‌کشی تلمبه‌خانه رفسنجان | B13: 7 | C13: Pipe | D13: PIPE HFW WELDED, API 5L GRADE X60, DOUBLE RANDOM LENGTHS OF 12 M. BEVELED END,BEVEL ENDS PER ANSI B 16.25., DIMENSIONS AND TOLERANCES TO ASME B36.10, TESTING, MARKING TO API 5L SCH 80 - 14" Pipe | E13: 14" | F13: M | G13: 150 | H13: 0 | I13: 208 | J13: =G13*H13 -> 0 | K13: =G13*I13 -> 31200 | L13: PIPE HFW WELDED, API 5L GRADE X60, DOUBLE RANDOM LENGTHS OF 12 M. BEVELED END,BEVEL ENDS PER ANSI B 16.25., DIMENSIONS AND TOLERANCES TO ASME B36.10, TESTING, MARKING TO API 5L AND SPECIFICTION NO. 870063-B-00-XXX-00-101-PI-0034.AND attachment 10 of contract.
A14: تجهیزات لوله‌کشی تلمبه‌خانه رفسنجان | B14: 8 | C14: Pipe | D14: PIPE HFW WELDED, API 5L GRADE X60, DOUBLE RANDOM LENGTHS OF 12 M. BEVELED END,BEVEL ENDS PER ANSI B 16.25., DIMENSIONS AND TOLERANCES TO ASME B36.10, TESTING, MARKING TO API 5L 25.4 mm - 14" Pipe | E14: 14" | F14: M | G14: 400 | H14: 0 | I14: 273 | J14: =G14*H14 -> 0 | K14: =G14*I14 -> 109200 | L14: PIPE HFW WELDED, API 5L GRADE X60, DOUBLE RANDOM LENGTHS OF 12 M. BEVELED END,BEVEL ENDS PER ANSI B 16.25., DIMENSIONS AND TOLERANCES TO ASME B36.10, TESTING, MARKING TO API 5L AND SPECIFICTION NO. 870063-B-00-XXX-00-101-PI-0034.AND attachment 10 of contract.
A15: تجهیزات لوله‌کشی تلمبه‌خانه رفسنجان | B15: 9 | C15: Gate Valve | D15: GATE VALVE FLANGED, CLASS 150, RAISED FACE, SERRATED FINISH, DESIGN CODE: ASME B16.34, BOLTED BONNET, BOLTED GLAND, SOLID WEDGE, OUTSIDE SCREW & YOKE, RISING STEM THROUGH HANDWHEEL, HANDWHEEL OPERATED, RENEWABLE SEAT, ANTI BLOWOUT STEM. DIMENSIONS TO ANSI B 16.10 BODY: C.S., ASTM A 216 GR. WCB 150# 6" Gate Valve | E15: 6" | F15: NO | G15: 2 | H15: 0 | I15: 531.43 | J15: =G15*H15 -> 0 | K15: =G15*I15 -> 1062.86 | L15: GATE VALVE FLANGED, CLASS 150, RAISED FACE, SERRATED FINISH, DESIGN CODE: ASME B16.34, BOLTED BONNET, BOLTED GLAND, SOLID WEDGE, OUTSIDE SCREW & YOKE, RISING STEM THROUGH HANDWHEEL, HANDWHEEL OPERATED, RENEWABLE SEAT, ANTI BLOWOUT STEM. DIMENSIONS TO ANSI B 16.10 BODY: C.S., ASTM A 216 GR. WCB TRIM : F6 PACKING: SPIRAL WOUND ,ASBESTOS FREE.
A16: تجهیزات لوله‌کشی تلمبه‌خانه رفسنجان | B16: 10 | C16: Gate Valve | D16: GAT VALVE WITH POST INDICATOR FLANGED, CLASS 150, RAISED FACE, SERRATED FINISH, DESIGN CODE: ASME B16.34, BOLTED BONNET, BOLTED GLAND, SOLID WEDGE, OUTSIDE SCREW & YOKE, RISING STEM THROUGH HANDWHEEL, HANDWHEEL OPERATED, RENEWABLE SEAT, ANTI BLOWOUT STEM. DIMENSIONS TO ANSI B 16.10 BODY: C.S., ASTM A 216 GR. WCB 150# 12" Gate Valve | E16: 12" | F16: NO | G16: 3 | H16: 0 | I16: 1280.19 | J16: =G16*H16 -> 0 | K16: =G16*I16 -> 3840.57 | L16: GATE VALVE WITH POST INDICATOR FLANGED, CLASS 150, RAISED FACE, SERRATED FINISH, DESIGN CODE: ASME B16.34, BOLTED BONNET, BOLTED GLAND, SOLID WEDGE, OUTSIDE SCREW & YOKE, RISING STEM THROUGH HANDWHEEL, HANDWHEEL OPERATED, RENEWABLE SEAT, ANTI BLOWOUT STEM. DIMENSIONS TO ANSI B 16.10 BODY: C.S., ASTM A 216 GR. WCB TRIM : F6 PACKING: SPIRAL WOUND ,ASBESTOS FREE.
A17: تجهیزات لوله‌کشی تلمبه‌خانه رفسنجان | B17: 11 | C17: Check Valve | D17: CHECK VALVE FLANGED, RAISED FACE, SERRATED FINISH, CLASS 150, SWING TYPE, REGULAR PATTERN, BOLTED COVER, RENEWABLE SEAT. DESIGN CODE:ASME B16.34 BODY: C.S., ASTM A 216 GR. WCB TRIM : F6 GASKET:ASBESTOS FREE MATERIAL BOLTS & NUTS :ASTM A-197 GR.B7 & ASTM A-194 GR.2H 150# 6" Check Valve | E17: 6" | F17: NO | G17: 2 | H17: 0 | I17: 223.85 | J17: =G17*H17 -> 0 | K17: =G17*I17 -> 447.7 | L17: CHECK VALVE FLANGED, RAISED FACE, SERRATED FINISH, CLASS150, SWING TYPE, REGULAR PATTERN, BOLTED COVER, RENEWABLE SEAT. DESIGN CODE:ASME B16.34 BODY: C.S., ASTM A 216 GR. WCB TRIM : F6 GASKET:ASBESTOS FREE MATERIAL BOLTS & NUTS :ASTM A-197 GR.B7 & ASTM A-194 GR.2H
A18: تجهیزات لوله‌کشی تلمبه‌خانه رفسنجان | B18: 12 | C18: Check Valve | D18: CHECK VALVE FLANGED, RAISED FACE, SERRATED FINISH, CLASS 150, SWING TYPE, REGULAR PATTERN, BOLTED COVER, RENEWABLE SEAT. DESIGN CODE:ASME B16.34 BODY: C.S., ASTM A 216 GR. WCB TRIM : F6 GASKET:ASBESTOS FREE MATERIAL BOLTS & NUTS :ASTM A-197 GR.B7 & ASTM A-194 GR.2H 150# 12" Check Valve | E18: 12" | F18: NO | G18: 2 | H18: 0 | I18: 1767.8 | J18: =G18*H18 -> 0 | K18: =G18*I18 -> 3535.6
A19: تجهیزات لوله‌کشی تلمبه‌خانه رفسنجان | B19: 13 | C19: Check Valve | D19: CHECK VALVE FLANGED, RAISED FACE, SMOOTH FINISH, CLASS 300, SWING TYPE, REGULAR PATTERN, BOLTED COVER, RENEWABLE SEAT. DESIGN CODE:ASME B16.34 BODY: C.S., ASTM A 216 GR. WCB TRIM : F6 GASKET:ASBESTOS FREE MATERIAL 600# 14" Check Valve | E19: 14" | F19: NO | G19: 2 | H19: 0 | I19: 6185.32 | J19: =G19*H19 -> 0 | K19: =G19*I19 -> 12370.64 | L19: CHECK VALVE FLANGED, RAISED FACE, SMOOTH FINISH, CLASS 300, SWING TYPE, REGULAR PATTERN, BOLTED COVER, , RENEWABLE SEAT. DESIGN CODE:ASME B16.34 BODY: C.S., ASTM A 216 GR. WCB TRIM : F6 GASKET:ASBESTOS FREE MATERIAL BOLTS &NUTS :ASTM A-197 GR.B7 & ASTM A-194 GR.2H
A20: تجهیزات لوله‌کشی تلمبه‌خانه رفسنجان | B20: 14 | C20: Check Valve | D20: CHECK VALVE FLANGED, RAISED FACE, SMOOTH FINISH, CLASS 900, SWING TYPE, REGULAR PATTERN, BOLTED COVER, RENEWABLE SEAT. DESIGN CODE:ASME B16.34 BODY: C.S., ASTM A 216 GR. WCB TRIM : F6 GASKET:ASBESTOS FREE MATERIAL BOLTS &NUTS :ASTM A-197 GR.B7 & ASTM A-194 GR.2H 900# 14" Check Valve | E20: 14" | F20: NO | G20: 2 | H20: 0 | I20: 9292.13 | J20: =G20*H20 -> 0 | K20: =G20*I20 -> 18584.26 | L20: CHECK VALVE FLANGED, RAISED FACE, SMOOTH FINISH, CLASS 900, SWING TYPE, REGULAR PATTERN, BOLTED COVER, , RENEWABLE SEAT. DESIGN CODE:ASME B16.34 BODY: C.S., ASTM A 216 GR. WCB TRIM : F6 GASKET:ASBESTOS FREE MATERIAL BOLTS &NUTS :ASTM A-197 GR.B7 & ASTM A-194 GR.2H
A21: تجهیزات لوله‌کشی تلمبه‌خانه رفسنجان | B21: 15 | C21: Check Valve | D21: CHECK VALVE FLANGED, RTJ, SMOOTH FINISH, CLASS 1500, SWING TYPE, REGULAR PATTERN, BOLTED COVER, RENEWABLE SEAT. DESIGN CODE:ASME B16.34 BODY: C.S., ASTM A 216 GR. WCB TRIM : F6 GASKET:ASBESTOS FREE MATERIAL BOLTS &NUTS :ASTM A-197 GR.B7 & ASTM A-194 GR.2H 1500# 14" Check Valve | E21: 14" | F21: NO | G21: 4 | H21: 0 | I21: 14069.71 | J21: =G21*H21 -> 0 | K21: =G21*I21 -> 56278.84 | L21: CHECK VALVE FLANGED, RTJ, SMOOTH FINISH, CLASS 1500, SWING TYPE, REGULAR PATTERN, BOLTED COVER, , RENEWABLE SEAT. DESIGN CODE:ASME B16.34 BODY: C.S., ASTM A 216 GR. WCB TRIM : F6 GASKET:ASBESTOS FREE MATERIAL BOLTS &NUTS :ASTM A-197 GR.B7 & ASTM A-194 GR.2H
A22: تجهیزات لوله‌کشی تلمبه‌خانه رفسنجان | B22: 16 | C22: Chock Valve | D22: CHOCK VALVE RTJ, SERRATED FINISH, CLASS 1500 acc. To attachment 1500# 8" Chock Valve | E22: 8" | F22: NO | G22: 1 | H22: 0 | I22: 5371.23 | J22: =G22*H22 -> 0 | K22: =G22*I22 -> 5371.23 | L22: CHOCK VALVE FLANGED, RTJ, SERRATED FINISH, CLASS 1500 acc . To attachment 10 of contract.
A23: تجهیزات لوله‌کشی تلمبه‌خانه رفسنجان | B23: 17 | C23: Chock Valve | D23: CHOCK VALVE FLANGED, RAISED FACE, SERRATED FINISH, CLASS 150 acc. To 150# 8" Chock Valve | E23: 8" | F23: NO | G23: 1 | H23: 0 | I23: 887.32 | J23: =G23*H23 -> 0 | K23: =G23*I23 -> 887.32 | L23: CHOCK VALVE FLANGED, RAISED FACE, SERRATED FINISH, CLASS 150 acc . To attachment 10 of contract.
A24: تجهیزات لوله‌کشی تلمبه‌خانه رفسنجان | B24: 18 | C24: Ball Valve | D24: BALL VALVE FLANGED, RTJ, SERRATED FINISH, CLASS 1500. REDUCED BORE, DESIGN CODE: ASME B16.34, BOLTED BONNET, BOLTED GLAND, GEAR OPERATED, RENEWABLE SEAT, ANTI BLOWOUT STEM. BODY: C.S., ASTM A 216 GR. WCB TRIM : F6 1500# 8" Ball Valve | E24: 8" | F24: NO | G24: 1 | H24: 0 | I24: 6446.8 | J24: =G24*H24 -> 0 | K24: =G24*I24 -> 6446.8 | L24: BALL VALVE FLANGED, RTJ, SERRATED FINISH, CLASS 1500. REDUCED BORE, DESIGN CODE: ASME B16.34 , BOLTED BONNET , BOLTED GLAND, GEAR OPERATED, RENEWABLE SEAT, ANTI BLOWOUT STEM. BODY: C.S., ASTM A 216 GR. WCB TRIM : F6 PACKING :SPIRAL WOUND,ABESTOS FREE MATERIAL EQUIPPED WITH LIMIT SWITCH
A25: تجهیزات لوله‌کشی تلمبه‌خانه رفسنجان | B25: 19 | C25: Ball Valve | D25: BALL VALVE FLANGED, RTJ, SERRATED FINISH, CLASS 1500. REDUCED BORE, DESIGN CODE: ASME B16.34, BOLTED BONNET, BOLTED GLAND, GEAR OPERATED, RENEWABLE SEAT, ANTI BLOWOUT STEM. BODY: C.S., ASTM A 216 GR. WCB TRIM : F6 GASKET: SPIRAL WOUND, ASBESTOS FREE MATERIAL EQUIPPED 1500# 14" Ball Valve | E25: 14" | F25: NO | G25: 2 | H25: 0 | I25: 14819.15 | J25: =G25*H25 -> 0 | K25: =G25*I25 -> 29638.3 | L25: BALL VALVE FLANGED, RTJ , SERRATED FINISH, CLASS 1500. REDUCED BORE, DESIGN CODE: ASME B16.34 , BOLTED BONNET , BOLTED GLAND, GEAR OPERATED, RENEWABLE SEAT, ANTI BLOWOUT STEM. BODY: C.S., ASTM A 216 GR. WCB TRIM : F6 PACKING :SPIRAL WOUND,ABESTOS FREE MATERIAL EQUIPPED WITH LIMIT SWITCH
A26: تجهیزات لوله‌کشی تلمبه‌خانه رفسنجان | B26: 20 | C26: Ball Valve | D26: BALL VALVE FLANGED, RAISED FACE, SERRATED FINISH, CLASS 600. REDUCED BORE, DESIGN CODE: ASME B16.34, BOLTED BONNET, BOLTED GLAND, GEAR OPERATED, RENEWABLE SEAT, ANTI BLOWOUT STEM. BODY: C.S., ASTM A 216 GR. WCB TRIM : F6 600# 14" Ball Valve | E26: 14" | F26: NO | G26: 2 | H26: 0 | I26: 10103.79 | J26: =G26*H26 -> 0 | K26: =G26*I26 -> 20207.58 | L26: BALL VALVE FLANGED, RAISED FACE, SERRATED FINISH, CLASS 600. REDUCED BORE, DESIGN CODE: ASME B16.34 , BOLTED BONNET , BOLTED GLAND, GEAR OPERATED, RENEWABLE SEAT, ANTI BLOWOUT STEM. BODY: C.S., ASTM A 216 GR. WCB TRIM : F6 PACKING :SPIRAL WOUND,ABESTOS FREE MATERIAL EQUIPPED WITH LIMIT SWITCH
A27: تجهیزات لوله‌کشی تلمبه‌خانه رفسنجان | B27: 21 | C27: GLOBE VALVE | D27: GLOBE VALVE CLASS 1500, FLANGED RTJ, TO ASME B16.34, BOLTED BONNET, BOLTED GLAND, OS & Y, GEAR OPERATED SWIVEL PLUG TYPE DISC BODY : FCS, ASTM A 216 WCB TRIM : F6 1500# 14" GLOBE VALVE | E27: 14" | F27: NO | G27: 1 | H27: 0 | I27: 19896.18 | J27: =G27*H27 -> 0 | K27: =G27*I27 -> 19896.18 | L27: GLOBE VALVE CLASS 1500, FLANGED RTJ, TO ASME B16.34, BOLTED BONNET, BOLTED GLAND, OS & Y, GEAR OPERATED SWIVEL PLUG TYPE DISC BODY : FCS, ASTM A 216 WCB TRIM : F6 PACKING: SPIRAL WOUND ,ASBESTOS FREE
A28: تجهیزات لوله‌کشی تلمبه‌خانه رفسنجان | B28: 22 | C28: balk | D28: Bulk Piping Equipment / بالك تجهيزات لوله‌کشی تلمبه‌خانه رفسنجان (مطابق شرح خدمات پیوست ۱۰) | E28: Bulk | F28: يكقلم | G28: 1 | H28: 0 | I28: 150000 | J28: =G28*H28 -> 0 | K28: =G28*I28 -> 150000 | L28: (مطابق شرح خدمات پیوست ۱۰)
D29: جمع کل بخش (Subtotal) | G29: =SUM(G7:G28) -> 1766 | J29: =SUM(J7:J28) -> 0 | K29: =SUM(K7:K28) -> 600867.88
B30: جدول شماره ۱-۲-۲: قیمت پیشنهادی برای خرید تجهیزات لوله‌کشی تلمبه‌خانه یزد
A31: unit | B31: ردیف (Item) | C31: عنوان | D31: شرح تجهیزات (Description) خلاصه | E31: سایز (Size) | F31: واحد (Unit) | G31: مقدار (Qty) | H31: بهای واحد ریالی (Unit Rial) | I31: بهای واحد ارزی (Unit Euro) | J31: بهای کل ریالی (Total Rial) | K31: بهای کل ارزی (Total Euro) | L31: توضیحات پیمان
A32: تجهیزات لوله‌کشی تلمبه‌خانه یزد | B32: 1 | C32: Pipe | D32: SCH 100 - 8" Pipe | E32: 8" | F32: M | G32: 60 | H32: 0 | I32: 91 | J32: =G32*H32 -> 0 | K32: =G32*I32 -> 5460 | L32: PIPE HFW WELDED., API 5L GRADE B, DOUBLE RANDOM LENGTHS OF 12 M. BEVELED ENDS PER ASME B 16.25., DIMENSIONS AND TOLERANCES TO ASME B36.10, TESTING, MARKING TO API 5L AND SPECIFICTION NO. 870063-B-00-XXX-00-101-PI-0034, BEVELED END,BEVEL ENDS PER ASME B 16.25.
A33: تجهیزات لوله‌کشی تلمبه‌خانه یزد | B33: 2 | C33: Pipe | D33: SCH 30 - 8" Pipe | E33: 8" | F33: M | G33: 48 | H33: 0 | I33: 44 | J33: =G33*H33 -> 0 | K33: =G33*I33 -> 2112
A34: تجهیزات لوله‌کشی تلمبه‌خانه یزد | B34: 3 | C34: Pipe | D34: SCH 80 - 8" Pipe | E34: 8" | F34: M | G34: 24 | H34: 0 | I34: 77.5 | J34: =G34*H34 -> 0 | K34: =G34*I34 -> 1860
A35: تجهیزات لوله‌کشی تلمبه‌خانه یزد | B35: 4 | C35: Pipe | D35: SCH 30 - 12" Pipe | E35: 12" | F35: M | G35: 200 | H35: 0 | I35: 80 | J35: =G35*H35 -> 0 | K35: =G35*I35 -> 16000
A36: تجهیزات لوله‌کشی تلمبه‌خانه یزد | B36: 5 | C36: Pipe | D36: SCH STD - 14" Pipe | E36: 14" | F36: M | G36: 1600 | H36: 0 | I36: 100 | J36: =G36*H36 -> 0 | K36: =G36*I36 -> 160000
A37: تجهیزات لوله‌کشی تلمبه‌خانه یزد | B37: 6 | C37: Pipe | D37: SCH STD - 16" Pipe | E37: 16" | F37: M | G37: 36 | H37: 0 | I37: 110 | J37: =G37*H37 -> 0 | K37: =G37*I37 -> 3960
A38: تجهیزات لوله‌کشی تلمبه‌خانه یزد | B38: 7 | C38: Pipe | D38: SCH 30 - 18" Pipe | E38: 18" | F38: M | G38: 200 | H38: 0 | I38: 145 | J38: =G38*H38 -> 0 | K38: =G38*I38 -> 29000
A39: تجهیزات لوله‌کشی تلمبه‌خانه یزد | B39: 8 | C39: Pipe | D39: PIPE SUBMERGED ARC WELDED., API 5L GRADE B, DOUBLE RANDOM LENGTHS OF 12 M. BEVELED ENDS PER ASME B 16.25., DIMENSIONS AND TOLERANCES TO ASME B36.10, TESTING, MARKING TO API 5L AND SPECIFICTION NO. 870063-B-00-XXX-00-101-PI-0034, BEVELED END,BEVEL ENDS PER ASME B 16.25. SCH STD - 28" Pipe | E39: 28" | F39: M | G39: 450 | H39: 0 | I39: 220 | J39: =G39*H39 -> 0 | K39: =G39*I39 -> 99000 | L39: PIPE SUBMERGED ARC WELDED., API 5L GRADE B, DOUBLE RANDOM LENGTHS OF 12 M. BEVELED ENDS PER ASME B 16.25., DIMENSIONS AND TOLERANCES TO ASME B36.10, TESTING, MARKING TO API 5L AND SPECIFICTION NO. 870063-B-00-XXX-00-101-PI-0034, BEVELED END,BEVEL ENDS PER ASME B 16.25.
A40: تجهیزات لوله‌کشی تلمبه‌خانه یزد | B40: 9 | C40: Pipe | D40: SCH 60 - 14" Pipe | E40: 14" | F40: M | G40: 90 | H40: 0 | I40: 170 | J40: =G40*H40 -> 0 | K40: =G40*I40 -> 15300 | L40: PIPE HFW WELDED., API 5L GRADE X52, DOUBLE RANDOM LENGTHS OF 12 M. BEVELED ENDS PER ASME B 16.25., DIMENSIONS AND TOLERANCES TO ASME B36.10, TESTING, MARKING TO API 5L AND SPECIFICTION NO. 870063-B-00-XXX-00-101-PI-0034. BEVELED END,BEVEL ENDS PER ASME B 16.25.
A41: تجهیزات لوله‌کشی تلمبه‌خانه یزد | B41: 10 | C41: Pipe | D41: SCH 60 - 16" Pipe | E41: 16" | F41: M | G41: 12 | H41: 0 | I41: 192 | J41: =G41*H41 -> 0 | K41: =G41*I41 -> 2304
...

Sheet Piping & Valves تجمعی
E1: پروژه احداث خط لوله ۱۶ اینچ انتقال فرآورده رفسنجان-یزد و توسعه مراکز انتقال نفت رفسنجان و یزد به روش EPC
E2: بخش لوله‌کشی و شیرآلات (Piping & Valves)
B3: ◀ بازگشت به داشبورد
B5: جدول شماره ۱-۱-۲: قیمت پیشنهادی برای خرید تجهیزات لوله‌کشی تلمبه‌خانه رفسنجان
A7: unit | B7: ردیف (Item) | C7: عنوان | D7: شرح تجهیزات (Description) خلاصه | E7: سایز (Size) | F7: واحد (Unit) | G7: مقدار (Qty) | H7: بهای واحد ریالی (Unit Rial) | I7: بهای واحد ارزی (Unit Euro) | J7: بهای کل ریالی (Total Rial) | K7: بهای کل ارزی (Total Euro) | L7: توضیحات پیمان
A8: تجهیزات لوله‌کشی تلمبه‌خانه رفسنجان | B8: 1 | C8: Pipe | D8: SCH 30 - 8" Pipe | E8: 8" | F8: M | G8: 96 | H8: 0 | I8: 45 | J8: =G8*H8 -> 0 | K8: =G8*I8 -> 4320 | L8: PIPE HFW WELDED, API 5L GRADE B, DOUBLE RANDOM LENGTHS OF 12 M. BEVELED END,BEVEL ENDS PER ANSI B 16.25., DIMENSIONS AND TOLERANCES TO ASME B36.10, TESTING, MARKING TO API 5L AND SPECIFICTION NO. 870063-B-00-XXX-00-101-PI-0034. AND attachment 10 of contract.
A9: تجهیزات لوله‌کشی تلمبه‌خانه رفسنجان | B9: 2 | C9: Pipe | D9: SCH 80 - 8" Pipe | E9: 8" | F9: M | G9: 72 | H9: 0 | I9: 45 | J9: =G9*H9 -> 0 | K9: =G9*I9 -> 3240
A10: تجهیزات لوله‌کشی تلمبه‌خانه رفسنجان | B10: 3 | C10: Pipe | D10: SCH 100 - 8" Pipe | E10: 8" | F10: M | G10: 72 | H10: 0 | I10: 45 | J10: =G10*H10 -> 0 | K10: =G10*I10 -> 3240
A11: تجهیزات لوله‌کشی تلمبه‌خانه رفسنجان | B11: 4 | C11: Pipe | D11: SCH 30 - 12" Pipe | E11: 12" | F11: M | G11: 150 | H11: 0 | I11: 64 | J11: =G11*H11 -> 0 | K11: =G11*I11 -> 9600
A12: تجهیزات لوله‌کشی تلمبه‌خانه رفسنجان | B12: 5 | C12: Pipe | D12: SCH STD - 16" Pipe | E12: 16" | F12: M | G12: 500 | H12: 0 | I12: 124 | J12: =G12*H12 -> 0 | K12: =G12*I12 -> 62000
A13: تجهیزات لوله‌کشی تلمبه‌خانه رفسنجان | B13: 6 | C13: Pipe | D13: PIPE HFW WELDED, API 5L GRADE X52, DOUBLE RANDOM LENGTHS OF 12 M. BEVELED END,BEVEL ENDS PER ANSI B 16.25., DIMENSIONS AND TOLERANCES TO ASME B36.10, TESTING, MARKING TO API 5L SCH 60 - 14" Pipe | E13: 14" | F13: M | G13: 300 | H13: 0 | I13: 165 | J13: =G13*H13 -> 0 | K13: =G13*I13 -> 49500 | L13: PIPE HFW WELDED, API 5L GRADE X52, DOUBLE RANDOM LENGTHS OF 12 M. BEVELED END,BEVEL ENDS PER ANSI B 16.25., DIMENSIONS AND TOLERANCES TO ASME B36.10, TESTING, MARKING TO API 5L AND SPECIFICTION NO. 870063-B-00-XXX-00-101-PI-0034.AND attachment 10 of contract.
A14: تجهیزات لوله‌کشی تلمبه‌خانه رفسنجان | B14: 7 | C14: Pipe | D14: PIPE HFW WELDED, API 5L GRADE X60, DOUBLE RANDOM LENGTHS OF 12 M. BEVELED END,BEVEL ENDS PER ANSI B 16.25., DIMENSIONS AND TOLERANCES TO ASME B36.10, TESTING, MARKING TO API 5L SCH 80 - 14" Pipe | E14: 14" | F14: M | G14: 150 | H14: 0 | I14: 208 | J14: =G14*H14 -> 0 | K14: =G14*I14 -> 31200 | L14: PIPE HFW WELDED, API 5L GRADE X60, DOUBLE RANDOM LENGTHS OF 12 M. BEVELED END,BEVEL ENDS PER ANSI B 16.25., DIMENSIONS AND TOLERANCES TO ASME B36.10, TESTING, MARKING TO API 5L AND SPECIFICTION NO. 870063-B-00-XXX-00-101-PI-0034.AND attachment 10 of contract.
A15: تجهیزات لوله‌کشی تلمبه‌خانه رفسنجان | B15: 8 | C15: Pipe | D15: PIPE HFW WELDED, API 5L GRADE X60, DOUBLE RANDOM LENGTHS OF 12 M. BEVELED END,BEVEL ENDS PER ANSI B 16.25., DIMENSIONS AND TOLERANCES TO ASME B36.10, TESTING, MARKING TO API 5L 25.4 mm - 14" Pipe | E15: 14" | F15: M | G15: 400 | H15: 0 | I15: 273 | J15: =G15*H15 -> 0 | K15: =G15*I15 -> 109200 | L15: PIPE HFW WELDED, API 5L GRADE X60, DOUBLE RANDOM LENGTHS OF 12 M. BEVELED END,BEVEL ENDS PER ANSI B 16.25., DIMENSIONS AND TOLERANCES TO ASME B36.10, TESTING, MARKING TO API 5L AND SPECIFICTION NO. 870063-B-00-XXX-00-101-PI-0034.AND attachment 10 of contract.
A16: تجهیزات لوله‌کشی تلمبه‌خانه رفسنجان | B16: 9 | C16: Gate Valve | D16: GATE VALVE FLANGED, CLASS 150, RAISED FACE, SERRATED FINISH, DESIGN CODE: ASME B16.34, BOLTED BONNET, BOLTED GLAND, SOLID WEDGE, OUTSIDE SCREW & YOKE, RISING STEM THROUGH HANDWHEEL, HANDWHEEL OPERATED, RENEWABLE SEAT, ANTI BLOWOUT STEM. DIMENSIONS TO ANSI B 16.10 BODY: C.S., ASTM A 216 GR. WCB 150# 6" Gate Valve | E16: 6" | F16: NO | G16: 2 | H16: 0 | I16: 531.43 | J16: =G16*H16 -> 0 | K16: =G16*I16 -> 1062.86 | L16: GATE VALVE FLANGED, CLASS 150, RAISED FACE, SERRATED FINISH, DESIGN CODE: ASME B16.34, BOLTED BONNET, BOLTED GLAND, SOLID WEDGE, OUTSIDE SCREW & YOKE, RISING STEM THROUGH HANDWHEEL, HANDWHEEL OPERATED, RENEWABLE SEAT, ANTI BLOWOUT STEM. DIMENSIONS TO ANSI B 16.10 BODY: C.S., ASTM A 216 GR. WCB TRIM : F6 PACKING: SPIRAL WOUND ,ASBESTOS FREE.
A17: تجهیزات لوله‌کشی تلمبه‌خانه رفسنجان | B17: 10 | C17: Gate Valve | D17: GAT VALVE WITH POST INDICATOR FLANGED, CLASS 150, RAISED FACE, SERRATED FINISH, DESIGN CODE: ASME B16.34, BOLTED BONNET, BOLTED GLAND, SOLID WEDGE, OUTSIDE SCREW & YOKE, RISING STEM THROUGH HANDWHEEL, HANDWHEEL OPERATED, RENEWABLE SEAT, ANTI BLOWOUT STEM. DIMENSIONS TO ANSI B 16.10 BODY: C.S., ASTM A 216 GR. WCB 150# 12" Gate Valve | E17: 12" | F17: NO | G17: 3 | H17: 0 | I17: 1280.19 | J17: =G17*H17 -> 0 | K17: =G17*I17 -> 3840.57 | L17: GATE VALVE WITH POST INDICATOR FLANGED, CLASS 150, RAISED FACE, SERRATED FINISH, DESIGN CODE: ASME B16.34, BOLTED BONNET, BOLTED GLAND, SOLID WEDGE, OUTSIDE SCREW & YOKE, RISING STEM THROUGH HANDWHEEL, HANDWHEEL OPERATED, RENEWABLE SEAT, ANTI BLOWOUT STEM. DIMENSIONS TO ANSI B 16.10 BODY: C.S., ASTM A 216 GR. WCB TRIM : F6 PACKING: SPIRAL WOUND ,ASBESTOS FREE.
A18: تجهیزات لوله‌کشی تلمبه‌خانه رفسنجان | B18: 11 | C18: Check Valve | D18: CHECK VALVE FLANGED, RAISED FACE, SERRATED FINISH, CLASS 150, SWING TYPE, REGULAR PATTERN, BOLTED COVER, RENEWABLE SEAT. DESIGN CODE:ASME B16.34 BODY: C.S., ASTM A 216 GR. WCB TRIM : F6 GASKET:ASBESTOS FREE MATERIAL BOLTS & NUTS :ASTM A-197 GR.B7 & ASTM A-194 GR.2H 150# 6" Check Valve | E18: 6" | F18: NO | G18: 2 | H18: 0 | I18: 223.85 | J18: =G18*H18 -> 0 | K18: =G18*I18 -> 447.7 | L18: CHECK VALVE FLANGED, RAISED FACE, SERRATED FINISH, CLASS150, SWING TYPE, REGULAR PATTERN, BOLTED COVER, RENEWABLE SEAT. DESIGN CODE:ASME B16.34 BODY: C.S., ASTM A 216 GR. WCB TRIM : F6 GASKET:ASBESTOS FREE MATERIAL BOLTS & NUTS :ASTM A-197 GR.B7 & ASTM A-194 GR.2H
A19: تجهیزات لوله‌کشی تلمبه‌خانه رفسنجان | B19: 12 | C19: Check Valve | D19: CHECK VALVE FLANGED, RAISED FACE, SERRATED FINISH, CLASS 150, SWING TYPE, REGULAR PATTERN, BOLTED COVER, RENEWABLE SEAT. DESIGN CODE:ASME B16.34 BODY: C.S., ASTM A 216 GR. WCB TRIM : F6 GASKET:ASBESTOS FREE MATERIAL BOLTS & NUTS :ASTM A-197 GR.B7 & ASTM A-194 GR.2H 150# 12" Check Valve | E19: 12" | F19: NO | G19: 2 | H19: 0 | I19: 1767.8 | J19: =G19*H19 -> 0 | K19: =G19*I19 -> 3535.6
A20: تجهیزات لوله‌کشی تلمبه‌خانه رفسنجان | B20: 13 | C20: Check Valve | D20: CHECK VALVE FLANGED, RAISED FACE, SMOOTH FINISH, CLASS 300, SWING TYPE, REGULAR PATTERN, BOLTED COVER, RENEWABLE SEAT. DESIGN CODE:ASME B16.34 BODY: C.S., ASTM A 216 GR. WCB TRIM : F6 GASKET:ASBESTOS FREE MATERIAL 600# 14" Check Valve | E20: 14" | F20: NO | G20: 2 | H20: 0 | I20: 6185.32 | J20: =G20*H20 -> 0 | K20: =G20*I20 -> 12370.64 | L20: CHECK VALVE FLANGED, RAISED FACE, SMOOTH FINISH, CLASS 300, SWING TYPE, REGULAR PATTERN, BOLTED COVER, , RENEWABLE SEAT. DESIGN CODE:ASME B16.34 BODY: C.S., ASTM A 216 GR. WCB TRIM : F6 GASKET:ASBESTOS FREE MATERIAL BOLTS &NUTS :ASTM A-197 GR.B7 & ASTM A-194 GR.2H
A21: تجهیزات لوله‌کشی تلمبه‌خانه رفسنجان | B21: 14 | C21: Check Valve | D21: CHECK VALVE FLANGED, RAISED FACE, SMOOTH FINISH, CLASS 900, SWING TYPE, REGULAR PATTERN, BOLTED COVER, RENEWABLE SEAT. DESIGN CODE:ASME B16.34 BODY: C.S., ASTM A 216 GR. WCB TRIM : F6 GASKET:ASBESTOS FREE MATERIAL BOLTS &NUTS :ASTM A-197 GR.B7 & ASTM A-194 GR.2H 900# 14" Check Valve | E21: 14" | F21: NO | G21: 2 | H21: 0 | I21: 9292.13 | J21: =G21*H21 -> 0 | K21: =G21*I21 -> 18584.26 | L21: CHECK VALVE FLANGED, RAISED FACE, SMOOTH FINISH, CLASS 900, SWING TYPE, REGULAR PATTERN, BOLTED COVER, , RENEWABLE SEAT. DESIGN CODE:ASME B16.34 BODY: C.S., ASTM A 216 GR. WCB TRIM : F6 GASKET:ASBESTOS FREE MATERIAL BOLTS &NUTS :ASTM A-197 GR.B7 & ASTM A-194 GR.2H
A22: تجهیزات لوله‌کشی تلمبه‌خانه رفسنجان | B22: 15 | C22: Check Valve | D22: CHECK VALVE FLANGED, RTJ, SMOOTH FINISH, CLASS 1500, SWING TYPE, REGULAR PATTERN, BOLTED COVER, RENEWABLE SEAT. DESIGN CODE:ASME B16.34 BODY: C.S., ASTM A 216 GR. WCB TRIM : F6 GASKET:ASBESTOS FREE MATERIAL BOLTS &NUTS :ASTM A-197 GR.B7 & ASTM A-194 GR.2H 1500# 14" Check Valve | E22: 14" | F22: NO | G22: 4 | H22: 0 | I22: 14069.71 | J22: =G22*H22 -> 0 | K22: =G22*I22 -> 56278.84 | L22: CHECK VALVE FLANGED, RTJ, SMOOTH FINISH, CLASS 1500, SWING TYPE, REGULAR PATTERN, BOLTED COVER, , RENEWABLE SEAT. DESIGN CODE:ASME B16.34 BODY: C.S., ASTM A 216 GR. WCB TRIM : F6 GASKET:ASBESTOS FREE MATERIAL BOLTS &NUTS :ASTM A-197 GR.B7 & ASTM A-194 GR.2H
A23: تجهیزات لوله‌کشی تلمبه‌خانه رفسنجان | B23: 16 | C23: Chock Valve | D23: CHOCK VALVE RTJ, SERRATED FINISH, CLASS 1500 acc. To attachment 1500# 8" Chock Valve | E23: 8" | F23: NO | G23: 1 | H23: 0 | I23: 5371.23 | J23: =G23*H23 -> 0 | K23: =G23*I23 -> 5371.23 | L23: CHOCK VALVE FLANGED, RTJ, SERRATED FINISH, CLASS 1500 acc . To attachment 10 of contract.
A24: تجهیزات لوله‌کشی تلمبه‌خانه رفسنجان | B24: 17 | C24: Chock Valve | D24: CHOCK VALVE FLANGED, RAISED FACE, SERRATED FINISH, CLASS 150 acc. To 150# 8" Chock Valve | E24: 8" | F24: NO | G24: 1 | H24: 0 | I24: 887.32 | J24: =G24*H24 -> 0 | K24: =G24*I24 -> 887.32 | L24: CHOCK VALVE FLANGED, RAISED FACE, SERRATED FINISH, CLASS 150 acc . To attachment 10 of contract.
A25: تجهیزات لوله‌کشی تلمبه‌خانه رفسنجان | B25: 18 | C25: Ball Valve | D25: BALL VALVE FLANGED, RTJ, SERRATED FINISH, CLASS 1500. REDUCED BORE, DESIGN CODE: ASME B16.34, BOLTED BONNET, BOLTED GLAND, GEAR OPERATED, RENEWABLE SEAT, ANTI BLOWOUT STEM. BODY: C.S., ASTM A 216 GR. WCB TRIM : F6 1500# 8" Ball Valve | E25: 8" | F25: NO | G25: 1 | H25: 0 | I25: 6446.8 | J25: =G25*H25 -> 0 | K25: =G25*I25 -> 6446.8 | L25: BALL VALVE FLANGED, RTJ, SERRATED FINISH, CLASS 1500. REDUCED BORE, DESIGN CODE: ASME B16.34 , BOLTED BONNET , BOLTED GLAND, GEAR OPERATED, RENEWABLE SEAT, ANTI BLOWOUT STEM. BODY: C.S., ASTM A 216 GR. WCB TRIM : F6 PACKING :SPIRAL WOUND,ABESTOS FREE MATERIAL EQUIPPED WITH LIMIT SWITCH
A26: تجهیزات لوله‌کشی تلمبه‌خانه رفسنجان | B26: 19 | C26: Ball Valve | D26: BALL VALVE FLANGED, RTJ, SERRATED FINISH, CLASS 1500. REDUCED BORE, DESIGN CODE: ASME B16.34, BOLTED BONNET, BOLTED GLAND, GEAR OPERATED, RENEWABLE SEAT, ANTI BLOWOUT STEM. BODY: C.S., ASTM A 216 GR. WCB TRIM : F6 GASKET: SPIRAL WOUND, ASBESTOS FREE MATERIAL EQUIPPED 1500# 14" Ball Valve | E26: 14" | F26: NO | G26: 2 | H26: 0 | I26: 14819.15 | J26: =G26*H26 -> 0 | K26: =G26*I26 -> 29638.3 | L26: BALL VALVE FLANGED, RTJ , SERRATED FINISH, CLASS 1500. REDUCED BORE, DESIGN CODE: ASME B16.34 , BOLTED BONNET , BOLTED GLAND, GEAR OPERATED, RENEWABLE SEAT, ANTI BLOWOUT STEM. BODY: C.S., ASTM A 216 GR. WCB TRIM : F6 PACKING :SPIRAL WOUND,ABESTOS FREE MATERIAL EQUIPPED WITH LIMIT SWITCH
A27: تجهیزات لوله‌کشی تلمبه‌خانه رفسنجان | B27: 20 | C27: Ball Valve | D27: BALL VALVE FLANGED, RAISED FACE, SERRATED FINISH, CLASS 600. REDUCED BORE, DESIGN CODE: ASME B16.34, BOLTED BONNET, BOLTED GLAND, GEAR OPERATED, RENEWABLE SEAT, ANTI BLOWOUT STEM. BODY: C.S., ASTM A 216 GR. WCB TRIM : F6 600# 14" Ball Valve | E27: 14" | F27: NO | G27: 2 | H27: 0 | I27: 10103.79 | J27: =G27*H27 -> 0 | K27: =G27*I27 -> 20207.58 | L27: BALL VALVE FLANGED, RAISED FACE, SERRATED FINISH, CLASS 600. REDUCED BORE, DESIGN CODE: ASME B16.34 , BOLTED BONNET , BOLTED GLAND, GEAR OPERATED, RENEWABLE SEAT, ANTI BLOWOUT STEM. BODY: C.S., ASTM A 216 GR. WCB TRIM : F6 PACKING :SPIRAL WOUND,ABESTOS FREE MATERIAL EQUIPPED WITH LIMIT SWITCH
A28: تجهیزات لوله‌کشی تلمبه‌خانه رفسنجان | B28: 21 | C28: GLOBE VALVE | D28: GLOBE VALVE CLASS 1500, FLANGED RTJ, TO ASME B16.34, BOLTED BONNET, BOLTED GLAND, OS & Y, GEAR OPERATED SWIVEL PLUG TYPE DISC BODY : FCS, ASTM A 216 WCB TRIM : F6 1500# 14" GLOBE VALVE | E28: 14" | F28: NO | G28: 1 | H28: 0 | I28: 19896.18 | J28: =G28*H28 -> 0 | K28: =G28*I28 -> 19896.18 | L28: GLOBE VALVE CLASS 1500, FLANGED RTJ, TO ASME B16.34, BOLTED BONNET, BOLTED GLAND, OS & Y, GEAR OPERATED SWIVEL PLUG TYPE DISC BODY : FCS, ASTM A 216 WCB TRIM : F6 PACKING: SPIRAL WOUND ,ASBESTOS FREE
A29: تجهیزات لوله‌کشی تلمبه‌خانه رفسنجان | B29: 22 | C29: BULK | D29: Bulk Piping Equipment / بالك تجهيزات لوله‌کشی تلمبه‌خانه رفسنجان (مطابق شرح خدمات پیوست ۱۰) | E29: Bulk | F29: يكقلم | G29: 1 | H29: 0 | I29: 150000 | J29: =G29*H29 -> 0 | K29: =G29*I29 -> 150000 | L29: (مطابق شرح خدمات پیوست ۱۰)
D30: جمع کل بخش (Subtotal) | G30: =SUM(G8:G29) -> 1766 | J30: =SUM(J8:J29) -> 0 | K30: =SUM(K8:K29) -> 600867.88
D32: جدول شماره ۱-۲-۲: قیمت پیشنهادی برای خرید تجهیزات لوله‌کشی تلمبه‌خانه یزد
A33: تجهیزات لوله‌کشی تلمبه‌خانه یزد | B33: 1 | C33: Pipe | D33: SCH 100 - 8" Pipe | E33: 8" | F33: M | G33: 60 | H33: 0 | I33: 91 | J33: =G33*H33 -> 0 | K33: =G33*I33 -> 5460 | L33: PIPE HFW WELDED., API 5L GRADE B, DOUBLE RANDOM LENGTHS OF 12 M. BEVELED ENDS PER ASME B 16.25., DIMENSIONS AND TOLERANCES TO ASME B36.10, TESTING, MARKING TO API 5L AND SPECIFICTION NO. 870063-B-00-XXX-00-101-PI-0034, BEVELED END,BEVEL ENDS PER ASME B 16.25.
A34: تجهیزات لوله‌کشی تلمبه‌خانه یزد | B34: 2 | C34: Pipe | D34: SCH 30 - 8" Pipe | E34: 8" | F34: M | G34: 48 | H34: 0 | I34: 44 | J34: =G34*H34 -> 0 | K34: =G34*I34 -> 2112
A35: تجهیزات لوله‌کشی تلمبه‌خانه یزد | B35: 3 | C35: Pipe | D35: SCH 80 - 8" Pipe | E35: 8" | F35: M | G35: 24 | H35: 0 | I35: 77.5 | J35: =G35*H35 -> 0 | K35: =G35*I35 -> 1860
A36: تجهیزات لوله‌کشی تلمبه‌خانه یزد | B36: 4 | C36: Pipe | D36: SCH 30 - 12" Pipe | E36: 12" | F36: M | G36: 200 | H36: 0 | I36: 80 | J36: =G36*H36 -> 0 | K36: =G36*I36 -> 16000
A37: تجهیزات لوله‌کشی تلمبه‌خانه یزد | B37: 5 | C37: Pipe | D37: SCH STD - 14" Pipe | E37: 14" | F37: M | G37: 1600 | H37: 0 | I37: 100 | J37: =G37*H37 -> 0 | K37: =G37*I37 -> 160000
A38: تجهیزات لوله‌کشی تلمبه‌خانه یزد | B38: 6 | C38: Pipe | D38: SCH STD - 16" Pipe | E38: 16" | F38: M | G38: 36 | H38: 0 | I38: 110 | J38: =G38*H38 -> 0 | K38: =G38*I38 -> 3960
A39: تجهیزات لوله‌کشی تلمبه‌خانه یزد | B39: 7 | C39: Pipe | D39: SCH 30 - 18" Pipe | E39: 18" | F39: M | G39: 200 | H39: 0 | I39: 145 | J39: =G39*H39 -> 0 | K39: =G39*I39 -> 29000
A40: تجهیزات لوله‌کشی تلمبه‌خانه یزد | B40: 8 | C40: Pipe | D40: PIPE SUBMERGED ARC WELDED., API 5L GRADE B, DOUBLE RANDOM LENGTHS OF 12 M. BEVELED ENDS PER ASME B 16.25., DIMENSIONS AND TOLERANCES TO ASME B36.10, TESTING, MARKING TO API 5L AND SPECIFICTION NO. 870063-B-00-XXX-00-101-PI-0034, BEVELED END,BEVEL ENDS PER ASME B 16.25. SCH STD - 28" Pipe | E40: 28" | F40: M | G40: 450 | H40: 0 | I40: 220 | J40: =G40*H40 -> 0 | K40: =G40*I40 -> 99000 | L40: PIPE SUBMERGED ARC WELDED., API 5L GRADE B, DOUBLE RANDOM LENGTHS OF 12 M. BEVELED ENDS PER ASME B 16.25., DIMENSIONS AND TOLERANCES TO ASME B36.10, TESTING, MARKING TO API 5L AND SPECIFICTION NO. 870063-B-00-XXX-00-101-PI-0034, BEVELED END,BEVEL ENDS PER ASME B 16.25.
A41: تجهیزات لوله‌کشی تلمبه‌خانه یزد | B41: 9 | C41: Pipe | D41: SCH 60 - 14" Pipe | E41: 14" | F41: M | G41: 90 | H41: 0 | I41: 170 | J41: =G41*H41 -> 0 | K41: =G41*I41 -> 15300 | L41: PIPE HFW WELDED., API 5L GRADE X52, DOUBLE RANDOM LENGTHS OF 12 M. BEVELED ENDS PER ASME B 16.25., DIMENSIONS AND TOLERANCES TO ASME B36.10, TESTING, MARKING TO API 5L AND SPECIFICTION NO. 870063-B-00-XXX-00-101-PI-0034. BEVELED END,BEVEL ENDS PER ASME B 16.25.
A42: تجهیزات لوله‌کشی تلمبه‌خانه یزد | B42: 10 | C42: Pipe | D42: SCH 60 - 16" Pipe | E42: 16" | F42: M | G42: 12 | H42: 0 | I42: 192 | J42: =G42*H42 -> 0 | K42: =G42*I42 -> 2304
A43: تجهیزات لوله‌کشی تلمبه‌خانه یزد | B43: 11 | C43: Pipe | D43: SCH 80 - 12" Pipe | E43: 12" | F43: M | G43: 200 | H43: 0 | I43: 160 | J43: =G43*H43 -> 0 | K43: =G43*I43 -> 32000 | L43: PIPE HFW WELDED., API 5L GRADE X60, DOUBLE RANDOM LENGTHS OF 12 M. BEVELED ENDS PER ASME B 16.25., DIMENSIONS AND TOLERANCES TO ASME B36.10, TESTING, MARKING TO API 5L AND SPECIFICTION NO. 870063-B-00-XXX-00-101-PI-0034. BEVELED END,BEVEL ENDS PER ASME B 16.25.
...

Sheet PIPING & VALVES جدول تفکیک قیمت
D1: پروژه احداث خط لوله ۱۶ اینچ انتقال فرآورده رفسنجان-یزد و توسعه مراکز انتقال نفت رفسنجان و یزد به روش EPC
B3: ◀ بازگشت به داشبورد
B5: به تفکیک هر قسمت پایپینک
B6: ردیف | C6: قسمت پایپینگ به تفکیک | F6: تجمعی ریال | K6: تجمعی یورویی
B7: 1 | C7: متریال PIPE | F7: =SUM(Piping!J29) -> 0 | K7: =SUM(Piping!K29) -> 753296
B8: 2 | C8: Ball Valve | F8: =SUM('Ball Valve'!J19) -> 0 | K8: =SUM('Ball Valve'!K19) -> 290207.68
B9: 3 | C9: Check Valve | F9: =SUM('Check Valve'!J23) -> 0 | K9: =SUM('Check Valve'!K23) -> 188213.04
B10: 4 | C10: Gate Valve | F10: =SUM('Gate Valve'!J16) -> 0 | K10: =SUM('Gate Valve'!K16) -> 127853.43
B11: 5 | C11: Chock Valve | F11: =SUM('Chock Valve'!J13) -> 0 | K11: =SUM('Chock Valve'!K13) -> 10858.55
B12: 6 | C12: GLOBE VALVE | F12: =SUM('GLOBE VALVE'!J10) -> 0 | K12: =SUM('GLOBE VALVE'!K10) -> 19896.18
B13: 7 | C13: EXPANSION JOINT | F13: =SUM('EXPANSION JOINT'!J12) -> 0 | K13: =SUM('EXPANSION JOINT'!K12) -> 99
B14: 8 | C14: bulk | F14: =SUM(bulk!J11) -> 0 | K14: =SUM(bulk!K11) -> 152500
B15: مجموع | F15: =SUM(F7:G14) -> 0 | K15: =SUM(K7:N14) -> 1542923.9

Sheet Piping
E1: پروژه احداث خط لوله ۱۶ اینچ انتقال فرآورده رفسنجان-یزد و توسعه مراکز انتقال نفت رفسنجان و یزد به روش EPC
E2: بخش لوله‌کشی و شیرآلات (Piping & Valves)
B3: ◀ بازگشت به داشبورد
A7: متریال PIPE
A8: ='Piping & Valves تجمعی'!A7 -> unit | B8: ='Piping & Valves تجمعی'!B7 -> ردیف (Item) | C8: ='Piping & Valves تجمعی'!C7 -> عنوان | D8: ='Piping & Valves تجمعی'!D7 -> شرح تجهیزات (Description) خلاصه | E8: ='Piping & Valves تجمعی'!E7 -> سایز (Size) | F8: ='Piping & Valves تجمعی'!F7 -> واحد (Unit) | G8: ='Piping & Valves تجمعی'!G7 -> مقدار (Qty) | H8: ='Piping & Valves تجمعی'!H7 -> بهای واحد ریالی (Unit Rial) | ... L8: ='Piping & Valves تجمعی'!L7 -> توضیحات پیمان
A9: ='Piping & Valves تجمعی'!A8 -> تجهیزات لوله‌کشی تلمبه‌خانه رفسنجان | B9: ='Piping & Valves تجمعی'!B8 -> 1 | C9: ='Piping & Valves تجمعی'!C8 -> Pipe | D9: ='Piping & Valves تجمعی'!D8 -> SCH 30 - 8" Pipe | E9: ='Piping & Valves تجمعی'!E8 -> 8" | F9: ='Piping & Valves تجمعی'!F8 -> M | G9: ='Piping & Valves تجمعی'!G8 -> 96 | H9: ='Piping & Valves تجمعی'!H8 -> 0 | ... L9: ='Piping & Valves تجمعی'!L8 -> PIPE HFW WELDED, API 5L GRADE B, DOUBLE RANDOM LENGTHS OF 12 M. BEVELED END,BEVEL ENDS PER ANSI B 16.25., DIMENSIONS AND TOLERANCES TO ASME B36.10, TESTING, MARKING TO API 5L AND SPECIFICTION NO. 870063-B-00-XXX-00-101-PI-0034. AND attachment 10 of contract.
A10: ='Piping & Valves تجمعی'!A9 -> تجهیزات لوله‌کشی تلمبه‌خانه رفسنجان | B10: ='Piping & Valves تجمعی'!B9 -> 2 | C10: ='Piping & Valves تجمعی'!C9 -> Pipe | D10: ='Piping & Valves تجمعی'!D9 -> SCH 80 - 8" Pipe | E10: ='Piping & Valves تجمعی'!E9 -> 8" | F10: ='Piping & Valves تجمعی'!F9 -> M | G10: ='Piping & Valves تجمعی'!G9 -> 72 | H10: ='Piping & Valves تجمعی'!H9 -> 0 | ... K10: ='Piping & Valves تجمعی'!K9 -> 3240
A11: ='Piping & Valves تجمعی'!A10 -> تجهیزات لوله‌کشی تلمبه‌خانه رفسنجان | B11: ='Piping & Valves تجمعی'!B10 -> 3 | C11: ='Piping & Valves تجمعی'!C10 -> Pipe | D11: ='Piping & Valves تجمعی'!D10 -> SCH 100 - 8" Pipe | E11: ='Piping & Valves تجمعی'!E10 -> 8" | F11: ='Piping & Valves تجمعی'!F10 -> M | G11: ='Piping & Valves تجمعی'!G10 -> 72 | H11: ='Piping & Valves تجمعی'!H10 -> 0 | ... K11: ='Piping & Valves تجمعی'!K10 -> 3240
A12: ='Piping & Valves تجمعی'!A11 -> تجهیزات لوله‌کشی تلمبه‌خانه رفسنجان | B12: ='Piping & Valves تجمعی'!B11 -> 4 | C12: ='Piping & Valves تجمعی'!C11 -> Pipe | D12: ='Piping & Valves تجمعی'!D11 -> SCH 30 - 12" Pipe | E12: ='Piping & Valves تجمعی'!E11 -> 12" | F12: ='Piping & Valves تجمعی'!F11 -> M | G12: ='Piping & Valves تجمعی'!G11 -> 150 | H12: ='Piping & Valves تجمعی'!H11 -> 0 | ... K12: ='Piping & Valves تجمعی'!K11 -> 9600
A13: ='Piping & Valves تجمعی'!A12 -> تجهیزات لوله‌کشی تلمبه‌خانه رفسنجان | B13: ='Piping & Valves تجمعی'!B12 -> 5 | C13: ='Piping & Valves تجمعی'!C12 -> Pipe | D13: ='Piping & Valves تجمعی'!D12 -> SCH STD - 16" Pipe | E13: ='Piping & Valves تجمعی'!E12 -> 16" | F13: ='Piping & Valves تجمعی'!F12 -> M | G13: ='Piping & Valves تجمعی'!G12 -> 500 | H13: ='Piping & Valves تجمعی'!H12 -> 0 | ... K13: ='Piping & Valves تجمعی'!K12 -> 62000
A14: ='Piping & Valves تجمعی'!A13 -> تجهیزات لوله‌کشی تلمبه‌خانه رفسنجان | B14: ='Piping & Valves تجمعی'!B13 -> 6 | C14: ='Piping & Valves تجمعی'!C13 -> Pipe | D14: ='Piping & Valves تجمعی'!D13 -> PIPE HFW WELDED, API 5L GRADE X52, DOUBLE RANDOM LENGTHS OF 12 M. BEVELED END,BEVEL ENDS PER ANSI B 16.25., DIMENSIONS AND TOLERANCES TO ASME B36.10, TESTING, MARKING TO API 5L SCH 60 - 14" Pipe | E14: ='Piping & Valves تجمعی'!E13 -> 14" | F14: ='Piping & Valves تجمعی'!F13 -> M | G14: ='Piping & Valves تجمعی'!G13 -> 300 | H14: ='Piping & Valves تجمعی'!H13 -> 0 | ... L14: ='Piping & Valves تجمعی'!L13 -> PIPE HFW WELDED, API 5L GRADE X52, DOUBLE RANDOM LENGTHS OF 12 M. BEVELED END,BEVEL ENDS PER ANSI B 16.25., DIMENSIONS AND TOLERANCES TO ASME B36.10, TESTING, MARKING TO API 5L AND SPECIFICTION NO. 870063-B-00-XXX-00-101-PI-0034.AND attachment 10 of contract.
A15: ='Piping & Valves تجمعی'!A14 -> تجهیزات لوله‌کشی تلمبه‌خانه رفسنجان | B15: ='Piping & Valves تجمعی'!B14 -> 7 | C15: ='Piping & Valves تجمعی'!C14 -> Pipe | D15: ='Piping & Valves تجمعی'!D14 -> PIPE HFW WELDED, API 5L GRADE X60, DOUBLE RANDOM LENGTHS OF 12 M. BEVELED END,BEVEL ENDS PER ANSI B 16.25., DIMENSIONS AND TOLERANCES TO ASME B36.10, TESTING, MARKING TO API 5L SCH 80 - 14" Pipe | E15: ='Piping & Valves تجمعی'!E14 -> 14" | F15: ='Piping & Valves تجمعی'!F14 -> M | G15: ='Piping & Valves تجمعی'!G14 -> 150 | H15: ='Piping & Valves تجمعی'!H14 -> 0 | ... L15: ='Piping & Valves تجمعی'!L14 -> PIPE HFW WELDED, API 5L GRADE X60, DOUBLE RANDOM LENGTHS OF 12 M. BEVELED END,BEVEL ENDS PER ANSI B 16.25., DIMENSIONS AND TOLERANCES TO ASME B36.10, TESTING, MARKING TO API 5L AND SPECIFICTION NO. 870063-B-00-XXX-00-101-PI-0034.AND attachment 10 of contract.
A16: ='Piping & Valves تجمعی'!A15 -> تجهیزات لوله‌کشی تلمبه‌خانه رفسنجان | B16: ='Piping & Valves تجمعی'!B15 -> 8 | C16: ='Piping & Valves تجمعی'!C15 -> Pipe | D16: ='Piping & Valves تجمعی'!D15 -> PIPE HFW WELDED, API 5L GRADE X60, DOUBLE RANDOM LENGTHS OF 12 M. BEVELED END,BEVEL ENDS PER ANSI B 16.25., DIMENSIONS AND TOLERANCES TO ASME B36.10, TESTING, MARKING TO API 5L 25.4 mm - 14" Pipe | E16: ='Piping & Valves تجمعی'!E15 -> 14" | F16: ='Piping & Valves تجمعی'!F15 -> M | G16: ='Piping & Valves تجمعی'!G15 -> 400 | H16: ='Piping & Valves تجمعی'!H15 -> 0 | ... L16: ='Piping & Valves تجمعی'!L15 -> PIPE HFW WELDED, API 5L GRADE X60, DOUBLE RANDOM LENGTHS OF 12 M. BEVELED END,BEVEL ENDS PER ANSI B 16.25., DIMENSIONS AND TOLERANCES TO ASME B36.10, TESTING, MARKING TO API 5L AND SPECIFICTION NO. 870063-B-00-XXX-00-101-PI-0034.AND attachment 10 of contract.
A17: ='Piping & Valves تجمعی'!A33 -> تجهیزات لوله‌کشی تلمبه‌خانه یزد | B17: ='Piping & Valves تجمعی'!B33 -> 1 | C17: ='Piping & Valves تجمعی'!C33 -> Pipe | D17: ='Piping & Valves تجمعی'!D33 -> SCH 100 - 8" Pipe | E17: ='Piping & Valves تجمعی'!E33 -> 8" | F17: ='Piping & Valves تجمعی'!F33 -> M | G17: ='Piping & Valves تجمعی'!G33 -> 60 | H17: ='Piping & Valves تجمعی'!H33 -> 0 | ... L17: ='Piping & Valves تجمعی'!L33 -> PIPE HFW WELDED., API 5L GRADE B, DOUBLE RANDOM LENGTHS OF 12 M. BEVELED ENDS PER ASME B 16.25., DIMENSIONS AND TOLERANCES TO ASME B36.10, TESTING, MARKING TO API 5L AND SPECIFICTION NO. 870063-B-00-XXX-00-101-PI-0034, BEVELED END,BEVEL ENDS PER ASME B 16.25.
A18: ='Piping & Valves تجمعی'!A34 -> تجهیزات لوله‌کشی تلمبه‌خانه یزد | B18: ='Piping & Valves تجمعی'!B34 -> 2 | C18: ='Piping & Valves تجمعی'!C34 -> Pipe | D18: ='Piping & Valves تجمعی'!D34 -> SCH 30 - 8" Pipe | E18: ='Piping & Valves تجمعی'!E34 -> 8" | F18: ='Piping & Valves تجمعی'!F34 -> M | G18: ='Piping & Valves تجمعی'!G34 -> 48 | H18: ='Piping & Valves تجمعی'!H34 -> 0 | ... K18: ='Piping & Valves تجمعی'!K34 -> 2112
A19: ='Piping & Valves تجمعی'!A35 -> تجهیزات لوله‌کشی تلمبه‌خانه یزد | B19: ='Piping & Valves تجمعی'!B35 -> 3 | C19: ='Piping & Valves تجمعی'!C35 -> Pipe | D19: ='Piping & Valves تجمعی'!D35 -> SCH 80 - 8" Pipe | E19: ='Piping & Valves تجمعی'!E35 -> 8" | F19: ='Piping & Valves تجمعی'!F35 -> M | G19: ='Piping & Valves تجمعی'!G35 -> 24 | H19: ='Piping & Valves تجمعی'!H35 -> 0 | ... K19: ='Piping & Valves تجمعی'!K35 -> 1860
A20: ='Piping & Valves تجمعی'!A36 -> تجهیزات لوله‌کشی تلمبه‌خانه یزد | B20: ='Piping & Valves تجمعی'!B36 -> 4 | C20: ='Piping & Valves تجمعی'!C36 -> Pipe | D20: ='Piping & Valves تجمعی'!D36 -> SCH 30 - 12" Pipe | E20: ='Piping & Valves تجمعی'!E36 -> 12" | F20: ='Piping & Valves تجمعی'!F36 -> M | G20: ='Piping & Valves تجمعی'!G36 -> 200 | H20: ='Piping & Valves تجمعی'!H36 -> 0 | ... K20: ='Piping & Valves تجمعی'!K36 -> 16000
A21: ='Piping & Valves تجمعی'!A37 -> تجهیزات لوله‌کشی تلمبه‌خانه یزد | B21: ='Piping & Valves تجمعی'!B37 -> 5 | C21: ='Piping & Valves تجمعی'!C37 -> Pipe | D21: ='Piping & Valves تجمعی'!D37 -> SCH STD - 14" Pipe | E21: ='Piping & Valves تجمعی'!E37 -> 14" | F21: ='Piping & Valves تجمعی'!F37 -> M | G21: ='Piping & Valves تجمعی'!G37 -> 1600 | H21: ='Piping & Valves تجمعی'!H37 -> 0 | ... K21: ='Piping & Valves تجمعی'!K37 -> 160000
A22: ='Piping & Valves تجمعی'!A38 -> تجهیزات لوله‌کشی تلمبه‌خانه یزد | B22: ='Piping & Valves تجمعی'!B38 -> 6 | C22: ='Piping & Valves تجمعی'!C38 -> Pipe | D22: ='Piping & Valves تجمعی'!D38 -> SCH STD - 16" Pipe | E22: ='Piping & Valves تجمعی'!E38 -> 16" | F22: ='Piping & Valves تجمعی'!F38 -> M | G22: ='Piping & Valves تجمعی'!G38 -> 36 | H22: ='Piping & Valves تجمعی'!H38 -> 0 | ... K22: ='Piping & Valves تجمعی'!K38 -> 3960
